Workbook

Sheet Legend
A1: Pair | B1: The (currency) pair of the trade that was taken | F1: All trades are executed using candle closure for an entry
A2: Date | B2: The date that the trade opened | F2: All trades are executed using conservative stop-losses
A3: Open time | B3: The exact time (hh:mm) a trade was opened | F3: All trades are executed using a risk:reward of 1:1
A4: Closing time | B4: The exact time (hh:mm) a trade was closed
A5: Order | B5: The type of order that was executed (long/short)
A6: Day | B6: What day of the week the trade was opened
A7: Session | B7: In what session the trade was opened
A8: Setup | B8: What pattern was used to open the trade
A9: News | B9: Whether there was a news event present during this trade
A10: Result | B10: What the result of the given trade is (win/loss)
A11: Mutation | B11: The mutation that the given trade resulted in, expressed in percentage
A12: Max. drawdown | B12: If a trade won, what the maximum amount of drawdown was (from open to highest/lowest wick)
A13: Max. result | B13: What the maximum risk:reward ratio of the given trade was
A14: Screenshot 4H | B14: A screenshot of the given trade on the 4 hour timeframe
A15: Screenshot 30min | B15: A screenshot of the given trade on the 30 minute timeframe
... A28: AOHOTL | B28: Amount of hits on target level

Sheet Data
A1: Pair | B1: Date | C1: Open time | D1: Closing time | E1: Order | F1: Day | G1: Session | H1: Setup | I1: 4H direction | J1: DoL | K1: ToL | L1: Level price | M1: PoBC | N1: PoBCfC | O1: AoPfB | P1: NLP | Q1: AOHOL | R1: AOHOTL | S1: Open | T1: High | U1: Low | V1: Close | W1: Result | X1: Mutation | Y1: Max. drawdown | Z1: Max. result | AA1: Screenshot 4H | AB1: Screenshot 30min | AC1: Screenshot 15min | AD1: Notes
A2: XAUUSD | B2: 45660 | C2: 0.26041667 | D2: 0.27083333 | E2: Sell | F2: Friday | G2: London | H2: Continuation | I2: Bullish | J2: 45660 | K2: 0.20833333 | L2: 2662.16 | P2: 2657.94 | Q2: 1 | R2: 4 | S2: 2662.7 | T2: 2662.8 | U2: 2660.98 | V2: 2661.34 | W2: Win | X2: 0.01 | Y2: 0.3 | Z2: 2.32 | AA2: https://www.tradingview.com/x/xnpOqAYi/ | AB2: https://www.tradingview.com/x/MU0nyts6/ | AC2: https://www.tradingview.com/x/mVnFS8i4/ | AD2: The max result is actually 32,21, but that would mean that you would have trade through multiple levels
A3: XAUUSD | B3: 45660 | C3: 0.5625 | D3: 0.59375 | E3: Sell | F3: Friday | G3: New York | H3: Continuation | I3: Bullish | J3: 45660 | K3: 0.52083333 | L3: 2656.7 | P3: 2652.46 | Q3: 1 | R3: 1 | S3: 2657.81 | T3: 2657.86 | U3: 2655.23 | V3: 2655.6 | W3: Win | X3: 0.01 | Y3: 17.7 | Z3: 1.39 | AA3: https://www.tradingview.com/x/xnpOqAYi/ | AC3: https://www.tradingview.com/x/U31jTson/ | AD3: The max result is actually 18,27, but that would mean that you would have trade through multiple levels
A4: XAUUSD | B4: 45663 | C4: 0.28125 | D4: 0.29166667 | E4: Sell | F4: Monday | G4: London | H4: Continuation | I4: Bearish | J4: 45659 | K4: 0.39583333 | L4: 2633.15 | P4: - | Q4: 1 | R4: - | S4: 2634.87 | T4: 2632.17 | U4: 2632.17 | V4: 2632.85 | W4: Loss | X4: -0.01 | Y4: - | Z4: 0.71 | AA4: https://www.tradingview.com/x/XpoqJ115/ | AB4: https://www.tradingview.com/x/Abn6e52g/ | AC4: https://www.tradingview.com/x/RgG5cyj6/
A5: XAUUSD | B5: 45663 | C5: 0.60416667 | D5: 0.61458333 | E5: Sell | F5: Monday | G5: New York | H5: Continuation | I5: Bearish | J5: 45663 | K5: 0.5625 | L5: 2642.33 | P5: 2626.73 | Q5: 0 | R5: 0 | S5: 2645.85 | T5: 2646.24 | U5: 2641.8 | V5: 2642.28 | W5: Win | X5: 0.01 | Y5: 2.4 | Z5: 3.92 | AA5: https://www.tradingview.com/x/1Qf7a0nY/ | AB5: https://www.tradingview.com/x/IB7tVyvO/ | AC5: https://www.tradingview.com/x/MusVpJs3/ | AD5: The max result is actually 7,06, but that would mean that you would have trade through multiple levels
A6: XAUUSD | B6: 45664 | C6: 0.53125 | D6: 0.54166667 | E6: Buy | F6: Tuesday | G6: New York | H6: Continuation | I6: Bullish | J6: 45663 | K6: 0.54166667 | L6: 2645.53 | P6: 2649.73 | Q6: 5 | R6: 1 | S6: 2645.43 | T6: 2646.67 | U6: 2644.54 | V6: 2646.57 | W6: Win | X6: 0.01 | Y6: 1.9 | Z6: 1.55 | AA6: https://www.tradingview.com/x/noefuquG/ | AB6: https://www.tradingview.com/x/sX9x4u6R/ | AC6: https://www.tradingview.com/x/6KGkOsgW/ | AD6: The max result is actually 8,69, but that would mean that you would have trade through multiple levels
A7: XAUUSD | B7: 45665 | C7: 0.30208333 | D7: 0.32291667 | E7: Buy | F7: Wednesday | G7: London | H7: Continuation | I7: Bullish | J7: 45665 | K7: 0.0625 | L7: 2650.81 | P7: 2654.82 | Q7: 1 | R7: 0 | S7: 2650.04 | T7: 2651.31 | U7: 2648.95 | V7: 2650.93 | W7: Win | X7: 0.01 | Y7: 4.9 | Z7: 1.71 | AA7: https://www.tradingview.com/x/x4iTZKKx/ | AB7: https://www.tradingview.com/x/oPN8P44K/ | AC7: https://www.tradingview.com/x/fCj6UJh5/
A8: XAUUSD | B8: 45665 | C8: 0.58333333 | D8: 0.59375 | E8: Buy | F8: Wednesday | G8: New York | H8: Continuation | I8: Bullish | J8: 45665 | K8: 0.54166667 | L8: 2650.79 | P8: 2654.82 | Q8: 1 | R8: 4 | S8: 2650.24 | T8: 2652.42 | U8: 2650.19 | V8: 2651.94 | W8: Win | X8: 0.01 | Y8: 4.3 | Z8: 1.65 | AA8: https://www.tradingview.com/x/hiy7l0ES/ | AB8: https://www.tradingview.com/x/YYmyL4kj/ | AC8: https://www.tradingview.com/x/Ugonmf0W/ | AD8: The max result is actually 10,36, but that would mean that you would have trade through multiple levels
A9: XAUUSD | B9: 45666 | C9: 0.3125 | D9: 0.32291667 | E9: Buy | F9: Thursday | G9: London | H9: Continuation | I9: Bullish | J9: 45666 | K9: 0.1875 | L9: 2659.92 | P9: 2663.37 | Q9: 2 | R9: 0 | S9: 2658.93 | T9: 2660.89 | U9: 2658.66 | V9: 2660.75 | W9: Win | X9: 0.01 | Y9: 4.1 | Z9: 1.26 | AA9: https://www.tradingview.com/x/9DPjKz6b/ | AB9: https://www.tradingview.com/x/zRDOHAGy/ | AC9: https://www.tradingview.com/x/KiF4mFdE/ | AD9: The max result is actually 8,42, but that would mean that you would have trade through multiple levels
A10: XAUUSD | B10: 45666 | C10: 0.57291667 | D10: 0.58333333 | E10: Buy | F10: Thursday | G10: New York | H10: Continuation | I10: Bullish | J10: 45639 | K10: 0.51041667 | L10: 2672.25 | P10: 2683.44 | Q10: 0 | R10: 0 | S10: 2672.12 | T10: 2674.46 | U10: 2671.66 | V10: 2672.75 | W10: Loss | X10: -0.01 | Y10: - | Z10: - | AA10: https://www.tradingview.com/x/Scgg4bfp/ | AB10: https://www.tradingview.com/x/cx7s0Izk/ | AC10: https://www.tradingview.com/x/QYqGYbH4/ | AD10: The SL got hit, right before it moved in the right direction and hit TP. It is hard to determine whether a flip happened or directly to SL, which would mean the trade wouldn't have been opened
A11: XAUUSD | B11: 45667 | C11: 0.28125 | D11: 0.32291667 | E11: Buy | F11: Friday | G11: London | H11: Continuation | I11: Bullish | J11: 45666 | K11: 0.60416667 | L11: 2674.96 | P11: 2683.44 | Q11: 3 | R11: 0 | S11: 2674 | T11: 2675.82 | U11: 2672.84 | V11: 2675.2 | W11: Win | X11: 0.01 | Y11: 13.1 | Z11: 3.28 | AA11: https://www.tradingview.com/x/zc572ZyN/ | AB11: https://www.tradingview.com/x/DJNHSLH9/ | AC11: https://www.tradingview.com/x/s16UFSdJ/
A12: XAUUSD | B12: 45670 | C12: 0.375 | D12: 0.38541667 | E12: Sell | F12: Monday | G12: London | H12: Continuation | I12: Bearish | J12: 45670 | K12: 0.27083333 | L12: 2685.09 | P12: 2680.47 | Q12: 1 | R12: 0 | S12: 2685.64 | T12: 2687.15 | U12: 2684.26 | V12: 2685.05 | W12: Loss | X12: -0.01 | Y12: - | Z12: 0.17 | AA12: https://www.tradingview.com/x/zSutV4Zl/ | AB12: https://www.tradingview.com/x/oWlK64qS/ | AC12: https://www.tradingview.com/x/SuiSwVJu/
A13: XAUUSD | B13: 45691 | C13: 0.63541667 | D13: 0.64583333 | E13: Buy | F13: Monday | G13: New York | H13: Continuation | I13: Bullish | J13: 45688 | K13: 0.66666667 | L13: 2812.31 | P13: - | Q13: 0 | R13: - | S13: 2810.89 | T13: 2814.65 | U13: 2809.98 | V13: 2814.23 | W13: Win | X13: 0.01 | Y13: 10.2 | Z13: 3.84 | AA13: https://www.tradingview.com/x/xMaukff8/ | AB13: https://www.tradingview.com/x/SkNsOwIh/ | AC13: https://www.tradingview.com/x/D9BIUApw/
A14: XAUUSD | B14: 45692 | C14: 0.26041667 | D14: 0.29166667 | E14: Sell | F14: Tuesday | G14: London | H14: Continuation | I14: Bearish | J14: 45692 | K14: 0.14583333 | L14: 2817.41 | P14: 2813.07 | Q14: 1 | R14: 0 | S14: 2818.9 | T14: 2819.07 | U14: 2813.28 | V14: 2816.49 | W14: Win | X14: 0.01 | Y14: 11.8 | Z14: 1.33 | AA14: https://www.tradingview.com/x/VDaWtATd/ | AB14: https://www.tradingview.com/x/wS6SXuoA/ | AC14: https://www.tradingview.com/x/pKMX4Qlg/ | AD14: The max result is actually 3,70, but that would mean that you would have trade through multiple levels
A15: XAUUSD | B15: 45692 | C15: 0.64583333 | D15: 0.66666667 | E15: Buy | F15: Tuesday | G15: New York | H15: Continuation | I15: Bullish | J15: 45692 | K15: 0.60416667 | L15: 2835.18 | P15: - | Q15: 1 | R15: - | S15: 2832.67 | T15: 2837.91 | U15: 2831.73 | V15: 2837.22 | W15: Win | X15: 0.01 | Y15: 13.8 | Z15: 1.46 | AA15: https://www.tradingview.com/x/SKeyj7XM/ | AB15: https://www.tradingview.com/x/PgRF3v8L/ | AC15: https://www.tradingview.com/x/KE0X8ttw/
A16: XAUUSD | B16: 45693 | C16: 0.28125 | D16: 0.30208333 | E16: Buy | F16: Wednesday | G16: London | H16: Continuation | I16: Bullish | J16: 45693 | K16: 0.22916667 | L16: 2856.38 | P16: - | Q16: 1 | R16: - | S16: 2856.02 | T16: 2858.97 | U16: 2855.27 | V16: 2857.97 | W16: Win | X16: 0.01 | Y16: 9 | Z16: 1.43 | AA16: https://www.tradingview.com/x/WMOQnYfJ/ | AB16: https://www.tradingview.com/x/LvKjd6p2/ | AC16: https://www.tradingview.com/x/l87L9VBn/
A17: XAUUSD | B17: 45693 | C17: 0.57291667 | D17: 0.58333333 | E17: Sell | F17: Wednesday | G17: New York | H17: Continuation | I17: Bullish | J17: 45693 | K17: 0.5 | L17: 2867.72 | P17: 2858 | Q17: 1 | R17: 0 | S17: 2869.01 | T17: 2870.26 | U17: 2867.04 | V17: 2867.37 | W17: Loss | X17: -0.01 | Y17: - | Z17: 0.13 | AA17: https://www.tradingview.com/x/4MmuA2Vt/ | AB17: https://www.tradingview.com/x/PvHsHIIc/ | AC17: https://www.tradingview.com/x/kjLtaEFP/
A18: XAUUSD | B18: 45694 | C18: 0.375 | D18: 0.38541667 | E18: Sell | F18: Thursday | G18: London | H18: Continuation | I18: Bearish | J18: 45693 | K18: 0.35416667 | L18: 2858 | P18: 2852.09 | Q18: 2 | R18: 0 | S18: 2858.15 | T18: 2858.2 | U18: 2854.78 | V18: 2855.59 | W18: Win | X18: 0.01 | Y18: 14.2 | Z18: 1.33 | AA18: https://www.tradingview.com/x/oAfqXVlO/ | AB18: https://www.tradingview.com/x/yjJ9RoJX/ | AC18: https://www.tradingview.com/x/ByzuSoft/ | AD18: The max result is actually 2,60, but that would mean that you would have trade through a level
A19: XAUUSD | B19: 45694 | C19: 0.53125 | D19: 0.58333333 | E19: Buy | F19: Thursday | G19: New York | H19: Continuation | I19: Bearish | J19: 45694 | K19: 0.35416667 | L19: 2860.92 | P19: 2871.42 | Q19: 4 | R19: 3 | S19: 28860.11 | T19: 2867.04 | U19: 28599.78 | V19: 2865.3 | W19: Loss | X19: -0.01 | Y19: - | Z19: 0.87 | AA19: https://www.tradingview.com/x/oOsVSkl2/ | AB19: https://www.tradingview.com/x/O9qjFFCc/ | AC19: https://www.tradingview.com/x/di6WRsDN/
A20: XAUUSD | B20: 45695 | C20: 0.54166667 | D20: 0.55208333 | E20: Buy | F20: Friday | G20: New York | H20: Continuation | I20: Bullish | J20: 45695 | K20: 0.5 | L20: 2867.36 | P20: 2871.42 | Q20: 1 | R20: 3 | S20: 2866.31 | T20: 2868.2 | U20: 2865.38 | V20: 2867.6 | W20: Loss | X20: -0.01 | Y20: - | Z20: 0.11 | AA20: https://www.tradingview.com/x/VnSme37y/ | AB20: https://www.tradingview.com/x/2NI6Gvh1/ | AC20: https://www.tradingview.com/x/r6xgoSaO/
A21: XAUUSD | B21: 45698 | C21: 0.29166667 | D21: 0.30208333 | E21: Buy | F21: Monday | G21: London | H21: Continuation | I21: Bullish | J21: 45698 | K21: 0.25 | L21: 2879 | P21: 2882.87 | Q21: 0 | R21: 0 | S21: 2878.54 | T21: 2879.14 | U21: 2875.9 | V21: 2879.1 | W21: Win | X21: 0.01 | Y21: 4.4 | Z21: 1.18 | AA21: https://www.tradingview.com/x/qOP4Gz1m/ | AB21: https://www.tradingview.com/x/a7spfYr7/ | AC21: https://www.tradingview.com/x/52dtYQ3N/ | AD21: The max result is actually 19,84, but that would mean that you would have trade through multiple levels
A22: XAUUSD | B22: 45698 | C22: 0.53125 | D22: 0.59375 | E22: Buy | F22: Monday | G22: New York | H22: Continuation | I22: Bullish | J22: 45698 | K22: 0.45833333 | L22: 2902.71 | P22: - | Q22: 1 | R22: - | S22: 2899.9 | T22: 2905.05 | U22: 2899.66 | V22: 2903.82 | W22: Win | X22: 0.01 | Y22: 28 | Z22: 1.69 | AA22: https://www.tradingview.com/x/B41MYd4s/ | AB22: https://www.tradingview.com/x/KFaEUy9v/ | AC22: https://www.tradingview.com/x/WuxRSfxU/
A23: XAUUSD | B23: 45699 | C23: 0.28125 | D23: 0.29166667 | E23: Buy | F23: Tuesday | G23: London | H23: Continuation | I23: Bullish | J23: 45699 | K23: 0.1875 | L23: 2922.13 | P23: 2939.64 | Q23: 0 | R23: 0 | S23: 2918.07 | T23: 1928.1 | U23: 2910.57 | V23: 2910.97 | W23: Win | X23: 0.01 | Y23: 11 | Z23: 1.41 | AA23: https://www.tradingview.com/x/i8v9KGfr/ | AB23: https://www.tradingview.com/x/Ob5LlcIy/ | AC23: https://www.tradingview.com/x/wrWp3QPP/
A24: XAUUSD | B24: 45699 | C24: 0.51041667 | D24: 0.54166667 | E24: Buy | F24: Tuesday | G24: New York | H24: Continuation | I24: Bearish | J24: 45699 | K24: 0.47916667 | L24: 2905.17 | P24: 2909.66 | Q24: 0 | R24: 0 | S24: 2902.4 | T24: 2906.14 | U24: 2901.97 | V24: 2905.58 | W24: Loss | X24: -0.01 | Y24: - | Z24: 0.26 | AA24: https://www.tradingview.com/x/P1PEepV7/ | AB24: https://www.tradingview.com/x/7KE3AWdH/ | AC24: https://www.tradingview.com/x/XmTfesPJ/
A25: XAUUSD | B25: 45701 | C25: 0.59375 | D25: 0.61458333 | E25: Sell | F25: Thursday | G25: New York | H25: Continuation | I25: Bullish | J25: 45701 | K25: 0.52083333 | L25: 2916.7 | P25: 2911.5 | Q25: 2 | R25: 0 | S25: 2917.51 | T25: 2917.8 | U25: 2912.74 | V25: 2915.2 | W25: Win | X25: 0.01 | Y25: 12.8 | Z25: 1.42 | AA25: https://www.tradingview.com/x/tTvve8HV/ | AB25: https://www.tradingview.com/x/Ln2cupAl/ | AC25: https://www.tradingview.com/x/yXmPbJ6q/
A26: XAUUSD | B26: 45702 | C26: 0.3125 | D26: 0.32291667 | E26: Buy | F26: Friday | G26: London | H26: Continuation | I26: Bullish | J26: 45702 | K26: 0.10416667 | L26: 2931.39 | P26: 2939.64 | Q26: 3 | R26: 0 | S26: 2931.14 | T26: 2933.2 | U26: 2930.66 | V26: 2932.86 | W26: Win | X26: 0.01 | Y26: 4.6 | Z26: 1.76 | AA26: https://www.tradingview.com/x/03Rtudzv/ | AB26: https://www.tradingview.com/x/n0htUmMD/ | AC26: https://www.tradingview.com/x/OBAkEVdI/
A27: XAUUSD | B27: 45702 | C27: 0.52083333 | D27: 0.53125 | E27: Sell | F27: Friday | G27: New York | H27: Continuation | I27: Bullish | J27: 45702 | K27: 0.45833333 | L27: 2935.04 | P27: 2931.6 | Q27: 1 | R27: 0 | S27: 2935.08 | T27: 2936.13 | U27: 2933.89 | V27: 2934.03 | W27: Win | X27: 0.01 | Y27: 7.6 | Z27: 1.15 | AA27: https://www.tradingview.com/x/CyKAqhaZ/ | AB27: https://www.tradingview.com/x/7bo3S0VU/ | AC27: https://www.tradingview.com/x/KdjZsJnD/ | AD27: The max result is actually 27,24, but that would mean that you would have trade through multiple levels
A28: XAUUSD | B28: 45705 | C28: 0.29166667 | D28: 0.30208333 | E28: Sell | F28: Monday | G28: London | H28: Continuation | I28: Bullish | J28: 45705 | K28: 0.25 | L28: 2899.28 | P28: 2876.95 | Q28: 0 | R28: 1 | S28: 2901.83 | T28: 2902.37 | U28: 2896 | V28: 2896.21 | W28: Win | X28: 0.01 | Y28: 4.2 | Z28: 1.31 | AA28: https://www.tradingview.com/x/WEkEwJQC/ | AB28: https://www.tradingview.com/x/PS2rpJ2K/ | AC28: https://www.tradingview.com/x/yYULF9E7/
A29: XAUUSD | B29: 45705 | C29: 0.55208333 | D29: 0.65625 | E29: Sell | F29: Monday | G29: New York | H29: Continuation | I29: Bullish | J29: 45705 | K29: 0.47916667 | L29: 2898.17 | P29: 2889.49 | Q29: 1 | R29: 0 | S29: 2900.92 | T29: 2901.5 | U29: 2896.6 | V29: 2897.41 | W29: Loss | X29: -0.01 | Y29: - | Z29: 0.51 | AA29: https://www.tradingview.com/x/uimFSRUl/ | AB29: https://www.tradingview.com/x/TtT0tDos/ | AC29: https://www.tradingview.com/x/bQ2dXKc8/ | AD29: The breakout candle is rather big. The price action in the trade is also quite choppy. This might be a good rule to add regarding putting a trade break even
A30: XAUUSD | B30: 45706 | C30: 0.30208333 | D30: 0.36458333 | E30: Buy | F30: Tuesday | G30: London | H30: Continuation | I30: Bullish | J30: 45706 | K30: 0.27083333 | L30: 2913.01 | P30: 2926.65 | Q30: 1 | R30: 0 | S30: 2910.55 | T30: 2914.25 | U30: 2909.85 | V30: 2913.76 | W30: Loss | X30: -0.01 | Y30: - | Z30: 0.42 | AA30: https://www.tradingview.com/x/OvHDO0cI/ | AB30: https://www.tradingview.com/x/TXWR6YAJ/ | AC30: https://www.tradingview.com/x/NRSVtzVu/
A31: XAUUSD | B31: 45706 | C31: 0.54166667 | D31: 0.57291667 | E31: Buy | F31: Tuesday | G31: New York | H31: Continuation | I31: Bullish | J31: 45706 | K31: 0.35416667 | L31: 2913.48 | P31: 2926.65 | Q31: 0 | R31: 0 | S31: 2911.19 | T31: 2914.71 | U31: 2910.84 | V31: 2914.1 | W31: Win | X31: 0.01 | Y31: 20.3 | Z31: 1.79 | AA31: https://www.tradingview.com/x/hvoB8kie/ | AB31: https://www.tradingview.com/x/gdEu9lLj/ | AC31: https://www.tradingview.com/x/RWTTBiSI/ | AD31: The max result is actually 16,1, but that would mean that you would have trade through multiple levels. Given that I would probably have moved the trade to BE, the 1,79 was the max result before the price comes back to the entry level
A32: XAUUSD | B32: 45707 | C32: 0.51041667 | D32: 0.52083333 | E32: Sell | F32: Wednesday | G32: New York | H32: Continuation | I32: Bullish | J32: 45707 | K32: 0.47916667 | L32: 2944.17 | P32: 2938.49 | Q32: 2 | R32: 0 | S32: 2944.7 | T32: 2945.94 | U32: 2942.79 | V32: 2943.39 | W32: Win | X32: 0.01 | Y32: 10.6 | Z32: 1.92 | AA32: https://www.tradingview.com/x/nVVbu7B1/ | AB32: https://www.tradingview.com/x/ie5wk0KV/ | AC32: https://www.tradingview.com/x/EAxpnqKF/ | AD32: The max result is actually 9,78, but that would mean that you would have trade through multiple levels
A33: XAUUSD | B33: 45708 | C33: 0.29166667 | D33: 0.35416667 | E33: Buy | F33: Thursday | G33: London | H33: Continuation | I33: Bullish | J33: 45707 | K33: 0.4375 | L33: 2945.79 | P33: - | Q33: 3 | R33: - | S33: 2943.63 | T33: 2946.67 | U33: 2943.51 | V33: 2946.54 | W33: Win | X33: 0.01 | Y33: 29.1 | Z33: 2.73 | AA33: https://www.tradingview.com/x/9tIvy6Kc/ | AB33: https://www.tradingview.com/x/MgFjvrYY/ | AC33: https://www.tradingview.com/x/u6BBSWQW/
A34: XAUUSD | B34: 45708 | C34: 0.54166667 | D34: 0.55208333 | E34: Sell | F34: Thursday | G34: New York | H34: Continuation | I34: Bullish | J34: 45708 | K34: 0.375 | L34: 2948.84 | P34: 2945.73 | Q34: 1 | R34: 0 | S34: 2949.45 | T34: 2949.47 | U34: 2947.03 | V34: 2948.57 | W34: Loss | X34: -0.01 | Y34: - | Z34: - | AA34: https://www.tradingview.com/x/7SqeuW07/ | AB34: https://www.tradingview.com/x/FJ2M6hce/ | AC34: https://www.tradingview.com/x/2x14agmq/
A35: XAUUSD | B35: 45709 | C35: 0.26041667 | D35: 0.27083333 | E35: Buy | F35: Friday | G35: London | H35: Continuation | I35: Bearish | J35: 45709 | K35: 0.1875 | L35: 2928.07 | P35: 2916.96 | Q35: 1 | R35: 0 | S35: 2928.41 | T35: 2928.65 | U35: 2925.15 | V35: 2927.47 | W35: Win | X35: 0.01 | Y35: 8 | Z35: 1.2 | AA35: https://www.tradingview.com/x/cpEQMVkc/ | AB35: https://www.tradingview.com/x/SGqrLVKK/ | AC35: https://www.tradingview.com/x/y46zoHWS/
A36: XAUUSD | B36: 45709 | C36: 0.51041667 | D36: 0.53125 | E36: Buy | F36: Friday | G36: New York | H36: Continuation | I36: Bearish | J36: 45709 | K36: 0.35416667 | L36: 2930.67 | P36: 2938.96 | Q36: 4 | R36: 0 | S36: 2930.4 | T36: 2934.52 | U36: 2929.63 | V36: 2934.05 | W36: Loss | X36: -0.01 | Y36: - | Z36: 0.63 | AA36: https://www.tradingview.com/x/N2jhAQBw/ | AB36: https://www.tradingview.com/x/O8LtpaQO/ | AC36: https://www.tradingview.com/x/Vii7dEvT/
A37: XAUUSD | B37: 45712 | C37: 0.54166667 | D37: 0.55208333 | E37: Buy | F37: Monday | G37: New York | H37: Continuation | I37: Bearish | J37: 45712 | K37: 0.41666667 | L37: 2946.18 | P37: 2954.34 | Q37: 2 | R37: 2 | S37: 2944.42 | T37: 2947.96 | U37: 2944.28 | V37: 2947.45 | W37: Win | X37: 0.01 | Y37: 21.4 | Z37: 1.16 | AA37: https://www.tradingview.com/x/emwqkpe4/ | AB37: https://www.tradingview.com/x/wVG479NH/ | AC37: https://www.tradingview.com/x/u6590E2X/ | AD37: The max result is actually 2,74, but that would mean that you would have trade through multiple levels. Given that I would probably have moved the trade to BE, the 1,16 was the max result before the price comes back to the entry level
A38: XAUUSD | B38: 45713 | C38: 0.3125 | D38: 0.33333333 | E38: Sell | F38: Tuesday | G38: London | H38: Continuation | I38: Bearish | J38: 45712 | K38: 0.6875 | L38: 2935.64 | P38: 2916.96 | Q38: 1 | R38: 1 | S38: 2936.58 | T38: 2938.33 | U38: 2935.24 | V38: 2935.55 | W38: Loss | X38: -0.01 | Y38: - | Z38: 0.79 | AA38: https://www.tradingview.com/x/AVhR02vW/ | AB38: https://www.tradingview.com/x/spNYOUqB/ | AC38: https://www.tradingview.com/x/HNzJVe7Y/
A39: XAUUSD | B39: 45713 | C39: 0.55208333 | D39: 0.5625 | E39: Buy | F39: Tuesday | G39: New York | H39: Continuation | I39: Bearish | J39: 45713 | K39: 0.52083333 | L39: 2940.05 | P39: 2949.67 | Q39: 1 | R39: 0 | S39: 2938.52 | T39: 2940.65 | U39: 2938.33 | V39: 2940.4 | W39: Loss | X39: -0.01 | Y39: - | Z39: 0.36 | AA39: https://www.tradingview.com/x/Ghx6OG4b/ | AB39: https://www.tradingview.com/x/9Y2OmGG5/ | AC39: https://www.tradingview.com/x/0WbK6X65/
A40: XAUUSD | B40: 45714 | C40: 0.53125 | D40: 0.57291667 | E40: Buy | F40: Wednesday | G40: New York | H40: Continuation | I40: Bearish | J40: 45714 | K40: 0.47916667 | L40: 2914.08 | P40: 2920.99 | Q40: 0 | R40: 0 | S40: 2912.87 | T40: 2915.12 | U40: 2912.58 | V40: 2914.76 | W40: Loss | X40: -0.01 | Y40: - | Z40: 0.29 | AA40: https://www.tradingview.com/x/2x0bKUxU/ | AB40: https://www.tradingview.com/x/RLgUVfaH/ | AC40: https://www.tradingview.com/x/GUJK0XJt/
...

Sheet Aggregate
B4: Mutation
B5: Jan | C5: Feb | D5: mrt | E5: apr | F5: mei | G5: jun | H5: jul | I5: aug | J5: sep | K5: okt | L5: nov | M5: dec
A6: 2023 | B6: =IF( COUNTIFS(Data!B2:B1005, ">="&DATE(2023,1,1), Data!B2:B1005, "<"&DATE(2023,2,1)) = 0, "", SUMIFS(Data!X2:X1005, Data!B2:B1005, ">="&DATE(2023,1,1), Data!B2:B1005, "<"&DATE(2023,2,1)) ) | C6: =IF( COUNTIFS(Data!B2:B1005, ">="&DATE(2023,2,1), Data!B2:B1005, "<"&DATE(2023,3,1)) = 0, "", SUMIFS(Data!X2:X1005, Data!B2:B1005, ">="&DATE(2023,2,1), Data!B2:B1005, "<"&DATE(2023,3,1)) ) | D6: =IF( COUNTIFS(Data!B2:B1005, ">="&DATE(2023,3,1), Data!B2:B1005, "<"&DATE(2023,4,1)) = 0, "", SUMIFS(Data!X2:X1005, Data!B2:B1005, ">="&DATE(2023,3,1), Data!B2:B1005, "<"&DATE(2023,4,1)) ) | E6: =IF( COUNTIFS(Data!B2:B1005, ">="&DATE(2023,4,1), Data!B2:B1005, "<"&DATE(2023,5,1)) = 0, "", SUMIFS(Data!X2:X1005, Data!B2:B1005, ">="&DATE(2023,4,1), Data!B2:B1005, "<"&DATE(2023,5,1)) ) | F6: =IF( COUNTIFS(Data!B2:B1005, ">="&DATE(2023,5,1), Data!B2:B1005, "<"&DATE(2023,6,1)) = 0, "", SUMIFS(Data!X2:X1005, Data!B2:B1005, ">="&DATE(2023,5,1), Data!B2:B1005, "<"&DATE(2023,6,1)) ) | G6: =IF( COUNTIFS(Data!B2:B1005, ">="&DATE(2023,6,1), Data!B2:B1005, "<"&DATE(2023,7,1)) = 0, "", SUMIFS(Data!X2:X1005, Data!B2:B1005, ">="&DATE(2023,6,1), Data!B2:B1005, "<"&DATE(2023,7,1)) ) | H6: =IF( COUNTIFS(Data!B2:B1005, ">="&DATE(2023,7,1), Data!B2:B1005, "<"&DATE(2023,8,1)) = 0, "", SUMIFS(Data!X2:X1005, Data!B2:B1005, ">="&DATE(2023,7,1), Data!B2:B1005, "<"&DATE(2023,8,1)) ) | I6: =IF( COUNTIFS(Data!B2:B1005, ">="&DATE(2023,8,1), Data!B2:B1005, "<"&DATE(2023,9,1)) = 0, "", SUMIFS(Data!X2:X1005, Data!B2:B1005, ">="&DATE(2023,8,1), Data!B2:B1005, "<"&DATE(2023,9,1)) ) | J6: =IF( COUNTIFS(Data!B2:B1005, ">="&DATE(2023,9,1), Data!B2:B1005, "<"&DATE(2023,10,1)) = 0, "", SUMIFS(Data!X2:X1005, Data!B2:B1005, ">="&DATE(2023,9,1), Data!B2:B1005, "<"&DATE(2023,10,1)) ) | K6: =IF( COUNTIFS(Data!B2:B1005, ">="&DATE(2023,10,1), Data!B2:B1005, "<"&DATE(2023,11,1)) = 0, "", SUMIFS(Data!X2:X1005, Data!B2:B1005, ">="&DATE(2023,10,1), Data!B2:B1005, "<"&DATE(2023,11,1)) ) | L6: =IF( COUNTIFS(Data!B2:B1005, ">="&DATE(2023,11,1), Data!B2:B1005, "<"&DATE(2023,12,1)) = 0, "", SUMIFS(Data!X2:X1005, Data!B2:B1005, ">="&DATE(2023,11,1), Data!B2:B1005, "<"&DATE(2023,12,1)) ) | M6: =IF( COUNTIFS(Data!B2:B1005, ">="&DATE(2024,1,1), Data!B2:B1005, "<"&DATE(2024,2,1)) = 0, "", SUMIFS(Data!X2:X1005, Data!B2:B1005, ">="&DATE(2024,1,1), Data!B2:B1005, "<"&DATE(2024,2,1)) )
A7: 2024 | B7: =IF( COUNTIFS(Data!B2:B1005, ">="&DATE(2024,1,1), Data!B2:B1005, "<"&DATE(2024,2,1)) = 0, "", SUMIFS(Data!X2:X1005, Data!B2:B1005, ">="&DATE(2024,1,1), Data!B2:B1005, "<"&DATE(2024,2,1)) ) | C7: =IF( COUNTIFS(Data!B2:B1005, ">="&DATE(2024,2,1), Data!B2:B1005, "<"&DATE(2024,3,1)) = 0, "", SUMIFS(Data!X2:X1005, Data!B2:B1005, ">="&DATE(2024,2,1), Data!B2:B1005, "<"&DATE(2024,3,1)) ) | D7: =IF( COUNTIFS(Data!B2:B1005, ">="&DATE(2024,3,1), Data!B2:B1005, "<"&DATE(2024,4,1)) = 0, "", SUMIFS(Data!X2:X1005, Data!B2:B1005, ">="&DATE(2024,3,1), Data!B2:B1005, "<"&DATE(2024,4,1)) ) | E7: =IF( COUNTIFS(Data!B2:B1005, ">="&DATE(2024,4,1), Data!B2:B1005, "<"&DATE(2024,5,1)) = 0, "", SUMIFS(Data!X2:X1005, Data!B2:B1005, ">="&DATE(2024,4,1), Data!B2:B1005, "<"&DATE(2024,5,1)) ) | F7: =IF( COUNTIFS(Data!B2:B1005, ">="&DATE(2024,5,1), Data!B2:B1005, "<"&DATE(2024,6,1)) = 0, "", SUMIFS(Data!X2:X1005, Data!B2:B1005, ">="&DATE(2024,5,1), Data!B2:B1005, "<"&DATE(2024,6,1)) ) | G7: =IF( COUNTIFS(Data!B2:B1005, ">="&DATE(2024,6,1), Data!B2:B1005, "<"&DATE(2024,7,1)) = 0, "", SUMIFS(Data!X2:X1005, Data!B2:B1005, ">="&DATE(2024,6,1), Data!B2:B1005, "<"&DATE(2024,7,1)) ) | H7: =IF( COUNTIFS(Data!B2:B1005, ">="&DATE(2024,7,1), Data!B2:B1005, "<"&DATE(2024,8,1)) = 0, "", SUMIFS(Data!X2:X1005, Data!B2:B1005, ">="&DATE(2024,7,1), Data!B2:B1005, "<"&DATE(2024,8,1)) ) | I7: =IF( COUNTIFS(Data!B2:B1005, ">="&DATE(2024,8,1), Data!B2:B1005, "<"&DATE(2024,9,1)) = 0, "", SUMIFS(Data!X2:X1005, Data!B2:B1005, ">="&DATE(2024,8,1), Data!B2:B1005, "<"&DATE(2024,9,1)) ) | J7: =IF( COUNTIFS(Data!B2:B1005, ">="&DATE(2024,9,1), Data!B2:B1005, "<"&DATE(2024,10,1)) = 0, "", SUMIFS(Data!X2:X1005, Data!B2:B1005, ">="&DATE(2024,9,1), Data!B2:B1005, "<"&DATE(2024,10,1)) ) | K7: =IF( COUNTIFS(Data!B2:B1005, ">="&DATE(2024,10,1), Data!B2:B1005, "<"&DATE(2024,11,1)) = 0, "", SUMIFS(Data!X2:X1005, Data!B2:B1005, ">="&DATE(2024,10,1), Data!B2:B1005, "<"&DATE(2024,11,1)) ) | L7: =IF( COUNTIFS(Data!B2:B1005, ">="&DATE(2024,11,1), Data!B2:B1005, "<"&DATE(2024,12,1)) = 0, "", SUMIFS(Data!X2:X1005, Data!B2:B1005, ">="&DATE(2024,11,1), Data!B2:B1005, "<"&DATE(2024,12,1)) ) | M7: =IF( COUNTIFS(Data!B2:B1005, ">="&DATE(2024,12,1), Data!B2:B1005, "<"&DATE(2025,1,1)) = 0, "", SUMIFS(Data!X2:X1005, Data!B2:B1005, ">="&DATE(2024,12,1), Data!B2:B1005, "<"&DATE(2025,1,1)) )
A8: 2025 | B8: =IF( COUNTIFS(Data!B2:B1005, ">="&DATE(2025,1,1), Data!B2:B1005, "<"&DATE(2025,2,1)) = 0, "", SUMIFS(Data!X2:X1005, Data!B2:B1005, ">="&DATE(2025,1,1), Data!B2:B1005, "<"&DATE(2025,2,1)) ) -> 0.05 | C8: =IF( COUNTIFS(Data!B2:B1005, ">="&DATE(2025,2,1), Data!B2:B1005, "<"&DATE(2025,3,1)) = 0, "", SUMIFS(Data!X2:X1005, Data!B2:B1005, ">="&DATE(2025,2,1), Data!B2:B1005, "<"&DATE(2025,3,1)) ) -> 0.05 | D8: =IF( COUNTIFS(Data!B2:B1005, ">="&DATE(2025,3,1), Data!B2:B1005, "<"&DATE(2025,4,1)) = 0, "", SUMIFS(Data!X2:X1005, Data!B2:B1005, ">="&DATE(2025,3,1), Data!B2:B1005, "<"&DATE(2025,4,1)) ) -> -0.01 | E8: =IF( COUNTIFS(Data!B2:B1005, ">="&DATE(2025,4,1), Data!B2:B1005, "<"&DATE(2025,5,1)) = 0, "", SUMIFS(Data!X2:X1005, Data!B2:B1005, ">="&DATE(2025,4,1), Data!B2:B1005, "<"&DATE(2025,5,1)) ) -> -0.02 | F8: =IF( COUNTIFS(Data!B2:B1005, ">="&DATE(2025,5,1), Data!B2:B1005, "<"&DATE(2025,6,1)) = 0, "", SUMIFS(Data!X2:X1005, Data!B2:B1005, ">="&DATE(2025,5,1), Data!B2:B1005, "<"&DATE(2025,6,1)) ) | G8: =IF( COUNTIFS(Data!B2:B1005, ">="&DATE(2025,6,1), Data!B2:B1005, "<"&DATE(2025,7,1)) = 0, "", SUMIFS(Data!X2:X1005, Data!B2:B1005, ">="&DATE(2025,6,1), Data!B2:B1005, "<"&DATE(2025,7,1)) ) | H8: =IF( COUNTIFS(Data!B2:B1005, ">="&DATE(2025,7,1), Data!B2:B1005, "<"&DATE(2025,8,1)) = 0, "", SUMIFS(Data!X2:X1005, Data!B2:B1005, ">="&DATE(2025,7,1), Data!B2:B1005, "<"&DATE(2025,8,1)) ) | I8: =IF( COUNTIFS(Data!B2:B1005, ">="&DATE(2025,8,1), Data!B2:B1005, "<"&DATE(2025,9,1)) = 0, "", SUMIFS(Data!X2:X1005, Data!B2:B1005, ">="&DATE(2025,8,1), Data!B2:B1005, "<"&DATE(2025,9,1)) ) | J8: =IF( COUNTIFS(Data!B2:B1005, ">="&DATE(2025,9,1), Data!B2:B1005, "<"&DATE(2025,10,1)) = 0, "", SUMIFS(Data!X2:X1005, Data!B2:B1005, ">="&DATE(2025,9,1), Data!B2:B1005, "<"&DATE(2025,10,1)) ) | K8: =IF( COUNTIFS(Data!B2:B1005, ">="&DATE(2025,10,1), Data!B2:B1005, "<"&DATE(2025,11,1)) = 0, "", SUMIFS(Data!X2:X1005, Data!B2:B1005, ">="&DATE(2025,10,1), Data!B2:B1005, "<"&DATE(2025,11,1)) ) | L8: =IF( COUNTIFS(Data!B2:B1005, ">="&DATE(2025,11,1), Data!B2:B1005, "<"&DATE(2025,12,1)) = 0, "", SUMIFS(Data!X2:X1005, Data!B2:B1005, ">="&DATE(2025,11,1), Data!B2:B1005, "<"&DATE(2025,12,1)) ) | M8: =IF( COUNTIFS(Data!B2:B1005, ">="&DATE(2025,12,1), Data!B2:B1005, "<"&DATE(2026,1,1)) = 0, "", SUMIFS(Data!X2:X1005, Data!B2:B1005, ">="&DATE(2025,12,1), Data!B2:B1005, "<"&DATE(2026,1,1)) )
A9: Average | B9: =IFERROR(AVERAGEIF(B6:B8, "<>"),"") -> 0.05 | C9: =IFERROR(AVERAGEIF(C6:C8, "<>"),"") -> 0.05 | D9: =IFERROR(AVERAGEIF(D6:D8, "<>"),"") -> -0.01 | E9: =IFERROR(AVERAGEIF(E6:E8, "<>"),"") -> -0.02 | F9: =IFERROR(AVERAGEIF(F6:F8, "<>"),"") | G9: =IFERROR(AVERAGEIF(G6:G8, "<>"),"") | H9: =IFERROR(AVERAGEIF(H6:H8, "<>"),"") | I9: =IFERROR(AVERAGEIF(I6:I8, "<>"),"") | ... M9: =IFERROR(AVERAGEIF(M6:M8, "<>"),"")
B13: Average running time
B14: Jan | C14: Feb | D14: mrt | E14: apr | F14: mei | G14: jun | H14: jul | I14: aug | J14: sep | K14: okt | L14: nov | M14: dec
A15: 2023 | B15: =IFERROR(__xludf.DUMMYFUNCTION("IFERROR( ARRAYFORMULA(AVERAGE(FILTER(Data!D2:D1005 - Data!C2:C1005, Data!B2:B1005 >= DATE(2023,1,1), Data!B2:B1005 < DATE(2023,2,1)))), """" ) "),"") | C15: =IFERROR(__xludf.DUMMYFUNCTION("IFERROR( ARRAYFORMULA(AVERAGE(FILTER(Data!D2:D1005 - Data!C2:C1005, Data!B2:B1005 >= DATE(2023,2,1), Data!B2:B1005 < DATE(2023,3,1)))), """" ) "),"") | D15: =IFERROR(__xludf.DUMMYFUNCTION("IFERROR( ARRAYFORMULA(AVERAGE(FILTER(Data!D2:D1005 - Data!C2:C1005, Data!B2:B1005 >= DATE(2023,3,1), Data!B2:B1005 < DATE(2023,4,1)))), """" ) "),"") | E15: =IFERROR(__xludf.DUMMYFUNCTION("IFERROR( ARRAYFORMULA(AVERAGE(FILTER(Data!D2:D1005 - Data!C2:C1005, Data!B2:B1005 >= DATE(2023,4,1), Data!B2:B1005 < DATE(2023,5,1)))), """" ) "),"") | F15: =IFERROR(__xludf.DUMMYFUNCTION("IFERROR( ARRAYFORMULA(AVERAGE(FILTER(Data!D2:D1005 - Data!C2:C1005, Data!B2:B1005 >= DATE(2023,5,1), Data!B2:B1005 < DATE(2023,6,1)))), """" ) "),"") | G15: =IFERROR(__xludf.DUMMYFUNCTION("IFERROR( ARRAYFORMULA(AVERAGE(FILTER(Data!D2:D1005 - Data!C2:C1005, Data!B2:B1005 >= DATE(2023,6,1), Data!B2:B1005 < DATE(2023,7,1)))), """" ) "),"") | H15: =IFERROR(__xludf.DUMMYFUNCTION("IFERROR( ARRAYFORMULA(AVERAGE(FILTER(Data!D2:D1005 - Data!C2:C1005, Data!B2:B1005 >= DATE(2023,7,1), Data!B2:B1005 < DATE(2023,8,1)))), """" ) "),"") | I15: =IFERROR(__xludf.DUMMYFUNCTION("IFERROR( ARRAYFORMULA(AVERAGE(FILTER(Data!D2:D1005 - Data!C2:C1005, Data!B2:B1005 >= DATE(2023,8,1), Data!B2:B1005 < DATE(2023,9,1)))), """" ) "),"") | J15: =IFERROR(__xludf.DUMMYFUNCTION("IFERROR( ARRAYFORMULA(AVERAGE(FILTER(Data!D2:D1005 - Data!C2:C1005, Data!B2:B1005 >= DATE(2023,9,1), Data!B2:B1005 < DATE(2023,10,1)))), """" ) "),"") | K15: =IFERROR(__xludf.DUMMYFUNCTION("IFERROR( ARRAYFORMULA(AVERAGE(FILTER(Data!D2:D1005 - Data!C2:C1005, Data!B2:B1005 >= DATE(2023,10,1), Data!B2:B1005 < DATE(2023,11,1)))), """" ) "),"") | L15: =IFERROR(__xludf.DUMMYFUNCTION("IFERROR( ARRAYFORMULA(AVERAGE(FILTER(Data!D2:D1005 - Data!C2:C1005, Data!B2:B1005 >= DATE(2023,11,1), Data!B2:B1005 < DATE(2023,12,1)))), """" ) "),"") | M15: =IFERROR(__xludf.DUMMYFUNCTION("IFERROR( ARRAYFORMULA(AVERAGE(FILTER(Data!D2:D1005 - Data!C2:C1005, Data!B2:B1005 >= DATE(2023,12,1), Data!B2:B1005 < DATE(2024,1,1)))), """" ) "),"")
A16: 2024 | B16: =IFERROR(__xludf.DUMMYFUNCTION("IFERROR( ARRAYFORMULA(AVERAGE(FILTER(Data!D2:D1005 - Data!C2:C1005, Data!B2:B1005 >= DATE(2024,1,1), Data!B2:B1005 < DATE(2024,2,1)))), """" ) "),"") | C16: =IFERROR(__xludf.DUMMYFUNCTION("IFERROR( ARRAYFORMULA(AVERAGE(FILTER(Data!D2:D1005 - Data!C2:C1005, Data!B2:B1005 >= DATE(2024,2,1), Data!B2:B1005 < DATE(2024,3,1)))), """" ) "),"") | D16: =IFERROR(__xludf.DUMMYFUNCTION("IFERROR( ARRAYFORMULA(AVERAGE(FILTER(Data!D2:D1005 - Data!C2:C1005, Data!B2:B1005 >= DATE(2024,3,1), Data!B2:B1005 < DATE(2024,4,1)))), """" ) "),"") | E16: =IFERROR(__xludf.DUMMYFUNCTION("IFERROR( ARRAYFORMULA(AVERAGE(FILTER(Data!D2:D1005 - Data!C2:C1005, Data!B2:B1005 >= DATE(2024,4,1), Data!B2:B1005 < DATE(2024,5,1)))), """" ) "),"") | F16: =IFERROR(__xludf.DUMMYFUNCTION("IFERROR( ARRAYFORMULA(AVERAGE(FILTER(Data!D2:D1005 - Data!C2:C1005, Data!B2:B1005 >= DATE(2024,5,1), Data!B2:B1005 < DATE(2024,6,1)))), """" ) "),"") | G16: =IFERROR(__xludf.DUMMYFUNCTION("IFERROR( ARRAYFORMULA(AVERAGE(FILTER(Data!D2:D1005 - Data!C2:C1005, Data!B2:B1005 >= DATE(2024,6,1), Data!B2:B1005 < DATE(2024,7,1)))), """" ) "),"") | H16: =IFERROR(__xludf.DUMMYFUNCTION("IFERROR( ARRAYFORMULA(AVERAGE(FILTER(Data!D2:D1005 - Data!C2:C1005, Data!B2:B1005 >= DATE(2024,7,1), Data!B2:B1005 < DATE(2024,8,1)))), """" ) "),"") | I16: =IFERROR(__xludf.DUMMYFUNCTION("IFERROR( ARRAYFORMULA(AVERAGE(FILTER(Data!D2:D1005 - Data!C2:C1005, Data!B2:B1005 >= DATE(2024,8,1), Data!B2:B1005 < DATE(2024,9,1)))), """" ) "),"") | J16: =IFERROR(__xludf.DUMMYFUNCTION("IFERROR( ARRAYFORMULA(AVERAGE(FILTER(Data!D2:D1005 - Data!C2:C1005, Data!B2:B1005 >= DATE(2024,9,1), Data!B2:B1005 < DATE(2024,10,1)))), """" ) "),"") | K16: =IFERROR(__xludf.DUMMYFUNCTION("IFERROR( ARRAYFORMULA(AVERAGE(FILTER(Data!D2:D1005 - Data!C2:C1005, Data!B2:B1005 >= DATE(2024,10,1), Data!B2:B1005 < DATE(2024,11,1)))), """" ) "),"") | L16: =IFERROR(__xludf.DUMMYFUNCTION("IFERROR( ARRAYFORMULA(AVERAGE(FILTER(Data!D2:D1005 - Data!C2:C1005, Data!B2:B1005 >= DATE(2024,11,1), Data!B2:B1005 < DATE(2024,12,1)))), """" ) "),"") | M16: =IFERROR(__xludf.DUMMYFUNCTION("IFERROR( ARRAYFORMULA(AVERAGE(FILTER(Data!D2:D1005 - Data!C2:C1005, Data!B2:B1005 >= DATE(2024,12,1), Data!B2:B1005 < DATE(2025,1,1)))), """" ) "),"")
A17: 2025 | B17: =IFERROR(__xludf.DUMMYFUNCTION("IFERROR( ARRAYFORMULA(AVERAGE(FILTER(Data!D2:D1005 - Data!C2:C1005, Data!B2:B1005 >= DATE(2025,1,1), Data!B2:B1005 < DATE(2025,2,1)))), """" ) "),0.016098484848484862) -> 0.016098485 | C17: =IFERROR(__xludf.DUMMYFUNCTION("IFERROR( ARRAYFORMULA(AVERAGE(FILTER(Data!D2:D1005 - Data!C2:C1005, Data!B2:B1005 >= DATE(2025,2,1), Data!B2:B1005 < DATE(2025,3,1)))), """" ) "),0.02452956989247313) -> 0.02452957 | D17: =IFERROR(__xludf.DUMMYFUNCTION("IFERROR( ARRAYFORMULA(AVERAGE(FILTER(Data!D2:D1005 - Data!C2:C1005, Data!B2:B1005 >= DATE(2025,3,1), Data!B2:B1005 < DATE(2025,4,1)))), """" ) "),0.0168010752688172) -> 0.016801075 | E17: =IFERROR(__xludf.DUMMYFUNCTION("IFERROR( ARRAYFORMULA(AVERAGE(FILTER(Data!D2:D1005 - Data!C2:C1005, Data!B2:B1005 >= DATE(2025,4,1), Data!B2:B1005 < DATE(2025,5,1)))), """" ) "),0.015624999999999997) -> 0.015625 | F17: =IFERROR(__xludf.DUMMYFUNCTION("IFERROR( ARRAYFORMULA(AVERAGE(FILTER(Data!D2:D1005 - Data!C2:C1005, Data!B2:B1005 >= DATE(2025,5,1), Data!B2:B1005 < DATE(2025,6,1)))), """" ) "),"") | G17: =IFERROR(__xludf.DUMMYFUNCTION("IFERROR( ARRAYFORMULA(AVERAGE(FILTER(Data!D2:D1005 - Data!C2:C1005, Data!B2:B1005 >= DATE(2025,6,1), Data!B2:B1005 < DATE(2025,7,1)))), """" ) "),"") | H17: =IFERROR(__xludf.DUMMYFUNCTION("IFERROR( ARRAYFORMULA(AVERAGE(FILTER(Data!D2:D1005 - Data!C2:C1005, Data!B2:B1005 >= DATE(2025,7,1), Data!B2:B1005 < DATE(2025,8,1)))), """" ) "),"") | I17: =IFERROR(__xludf.DUMMYFUNCTION("IFERROR( ARRAYFORMULA(AVERAGE(FILTER(Data!D2:D1005 - Data!C2:C1005, Data!B2:B1005 >= DATE(2025,8,1), Data!B2:B1005 < DATE(2025,9,1)))), """" ) "),"") | J17: =IFERROR(__xludf.DUMMYFUNCTION("IFERROR( ARRAYFORMULA(AVERAGE(FILTER(Data!D2:D1005 - Data!C2:C1005, Data!B2:B1005 >= DATE(2025,9,1), Data!B2:B1005 < DATE(2025,10,1)))), """" ) "),"") | K17: =IFERROR(__xludf.DUMMYFUNCTION("IFERROR( ARRAYFORMULA(AVERAGE(FILTER(Data!D2:D1005 - Data!C2:C1005, Data!B2:B1005 >= DATE(2025,10,1), Data!B2:B1005 < DATE(2025,11,1)))), """" ) "),"") | L17: =IFERROR(__xludf.DUMMYFUNCTION("IFERROR( ARRAYFORMULA(AVERAGE(FILTER(Data!D2:D1005 - Data!C2:C1005, Data!B2:B1005 >= DATE(2025,11,1), Data!B2:B1005 < DATE(2025,12,1)))), """" ) "),"") | M17: =IFERROR(__xludf.DUMMYFUNCTION("IFERROR( ARRAYFORMULA(AVERAGE(FILTER(Data!D2:D1005 - Data!C2:C1005, Data!B2:B1005 >= DATE(2025,12,1), Data!B2:B1005 < DATE(2026,1,1)))), """" ) "),"")
A18: Average | B18: =IFERROR(AVERAGE(B15:B17),"") -> 0.016098485 | C18: =IFERROR(AVERAGE(C15:C17),"") -> 0.02452957 | D18: =IFERROR(AVERAGE(D15:D17),"") -> 0.016801075 | E18: =IFERROR(AVERAGE(E15:E17),"") -> 0.015625 | F18: =IFERROR(AVERAGE(F15:F17),"") | G18: =IFERROR(AVERAGE(G15:G17),"") | H18: =IFERROR(AVERAGE(H15:H17),"") | I18: =IFERROR(AVERAGE(I15:I17),"") | ... M18: =IFERROR(AVERAGE(M15:M17),"")
B22: Average running time losers
B23: Jan | C23: Feb | D23: mrt | E23: apr | F23: mei | G23: jun | H23: jul | I23: aug | J23: sep | K23: okt | L23: nov | M23: dec | R23: TODO: add this
A24: 2023 | B24: =IFERROR(__xludf.DUMMYFUNCTION("IFERROR(ARRAYFORMULA(AVERAGE(FILTER(Data!D2:D1005 - Data!C2:C1005, Data!B2:B1005 >= DATE(2023,1,1), Data!B2:B1005 < DATE(2023,2,1), Data!W2:W1005 = ""Loss""))),"""")"),"") | C24: =IFERROR(__xludf.DUMMYFUNCTION("IFERROR(ARRAYFORMULA(AVERAGE(FILTER(Data!D2:D1005 - Data!C2:C1005, Data!B2:B1005 >= DATE(2023,2,1), Data!B2:B1005 < DATE(2023,3,1), Data!W2:W1005 = ""Loss""))),"""")"),"") | D24: =IFERROR(__xludf.DUMMYFUNCTION("IFERROR(ARRAYFORMULA(AVERAGE(FILTER(Data!D2:D1005 - Data!C2:C1005, Data!B2:B1005 >= DATE(2023,3,1), Data!B2:B1005 < DATE(2023,4,1), Data!W2:W1005 = ""Loss""))),"""")"),"") | E24: =IFERROR(__xludf.DUMMYFUNCTION("IFERROR(ARRAYFORMULA(AVERAGE(FILTER(Data!D2:D1005 - Data!C2:C1005, Data!B2:B1005 >= DATE(2023,4,1), Data!B2:B1005 < DATE(2023,5,1), Data!W2:W1005 = ""Loss""))),"""")"),"") | F24: =IFERROR(__xludf.DUMMYFUNCTION("IFERROR(ARRAYFORMULA(AVERAGE(FILTER(Data!D2:D1005 - Data!C2:C1005, Data!B2:B1005 >= DATE(2023,5,1), Data!B2:B1005 < DATE(2023,6,1), Data!W2:W1005 = ""Loss""))),"""")"),"") | G24: =IFERROR(__xludf.DUMMYFUNCTION("IFERROR(ARRAYFORMULA(AVERAGE(FILTER(Data!D2:D1005 - Data!C2:C1005, Data!B2:B1005 >= DATE(2023,6,1), Data!B2:B1005 < DATE(2023,7,1), Data!W2:W1005 = ""Loss""))),"""")"),"") | H24: =IFERROR(__xludf.DUMMYFUNCTION("IFERROR(ARRAYFORMULA(AVERAGE(FILTER(Data!D2:D1005 - Data!C2:C1005, Data!B2:B1005 >= DATE(2023,7,1), Data!B2:B1005 < DATE(2023,8,1), Data!W2:W1005 = ""Loss""))),"""")"),"") | I24: =IFERROR(__xludf.DUMMYFUNCTION("IFERROR(ARRAYFORMULA(AVERAGE(FILTER(Data!D2:D1005 - Data!C2:C1005, Data!B2:B1005 >= DATE(2023,8,1), Data!B2:B1005 < DATE(2023,9,1), Data!W2:W1005 = ""Loss""))),"""")"),"") | J24: =IFERROR(__xludf.DUMMYFUNCTION("IFERROR(ARRAYFORMULA(AVERAGE(FILTER(Data!D2:D1005 - Data!C2:C1005, Data!B2:B1005 >= DATE(2023,9,1), Data!B2:B1005 < DATE(2023,10,1), Data!W2:W1005 = ""Loss""))),"""")"),"") | K24: =IFERROR(__xludf.DUMMYFUNCTION("IFERROR(ARRAYFORMULA(AVERAGE(FILTER(Data!D2:D1005 - Data!C2:C1005, Data!B2:B1005 >= DATE(2023,10,1), Data!B2:B1005 < DATE(2023,11,1), Data!W2:W1005 = ""Loss""))),"""")"),"") | L24: =IFERROR(__xludf.DUMMYFUNCTION("IFERROR(ARRAYFORMULA(AVERAGE(FILTER(Data!D2:D1005 - Data!C2:C1005, Data!B2:B1005 >= DATE(2023,11,1), Data!B2:B1005 < DATE(2023,12,1), Data!W2:W1005 = ""Loss""))),"""")"),"") | M24: =IFERROR(__xludf.DUMMYFUNCTION("IFERROR(ARRAYFORMULA(AVERAGE(FILTER(Data!D2:D1005 - Data!C2:C1005, Data!B2:B1005 >= DATE(2023,12,1), Data!B2:B1005 < DATE(2024,1,1), Data!W2:W1005 = ""Win""))),"""")"),"") | R24: Best day | S24: Worst day | T24: Best month | U24: Worst month
A25: 2024 | B25: =IFERROR(__xludf.DUMMYFUNCTION("IFERROR(ARRAYFORMULA(AVERAGE(FILTER(Data!D2:D1005 - Data!C2:C1005, Data!B2:B1005 >= DATE(2024,1,1), Data!B2:B1005 < DATE(2024,2,1), Data!W2:W1005 = ""Loss""))),"""")"),"") | C25: =IFERROR(__xludf.DUMMYFUNCTION("IFERROR(ARRAYFORMULA(AVERAGE(FILTER(Data!D2:D1005 - Data!C2:C1005, Data!B2:B1005 >= DATE(2024,2,1), Data!B2:B1005 < DATE(2024,3,1), Data!W2:W1005 = ""Loss""))),"""")"),"") | D25: =IFERROR(__xludf.DUMMYFUNCTION("IFERROR(ARRAYFORMULA(AVERAGE(FILTER(Data!D2:D1005 - Data!C2:C1005, Data!B2:B1005 >= DATE(2024,3,1), Data!B2:B1005 < DATE(2024,4,1), Data!W2:W1005 = ""Loss""))),"""")"),"") | E25: =IFERROR(__xludf.DUMMYFUNCTION("IFERROR(ARRAYFORMULA(AVERAGE(FILTER(Data!D2:D1005 - Data!C2:C1005, Data!B2:B1005 >= DATE(2024,4,1), Data!B2:B1005 < DATE(2024,5,1), Data!W2:W1005 = ""Win""))),"""")"),"") | F25: =IFERROR(__xludf.DUMMYFUNCTION("IFERROR(ARRAYFORMULA(AVERAGE(FILTER(Data!D2:D1005 - Data!C2:C1005, Data!B2:B1005 >= DATE(2024,5,1), Data!B2:B1005 < DATE(2024,6,1), Data!W2:W1005 = ""Win""))),"""")"),"") | G25: =IFERROR(__xludf.DUMMYFUNCTION("IFERROR(ARRAYFORMULA(AVERAGE(FILTER(Data!D2:D1005 - Data!C2:C1005, Data!B2:B1005 >= DATE(2024,6,1), Data!B2:B1005 < DATE(2024,7,1), Data!W2:W1005 = ""Loss""))),"""")"),"") | H25: =IFERROR(__xludf.DUMMYFUNCTION("IFERROR(ARRAYFORMULA(AVERAGE(FILTER(Data!D2:D1005 - Data!C2:C1005, Data!B2:B1005 >= DATE(2024,7,1), Data!B2:B1005 < DATE(2024,8,1), Data!W2:W1005 = ""Loss""))),"""")"),"") | I25: =IFERROR(__xludf.DUMMYFUNCTION("IFERROR(ARRAYFORMULA(AVERAGE(FILTER(Data!D2:D1005 - Data!C2:C1005, Data!B2:B1005 >= DATE(2024,8,1), Data!B2:B1005 < DATE(2024,9,1), Data!W2:W1005 = ""Loss""))),"""")"),"") | J25: =IFERROR(__xludf.DUMMYFUNCTION("IFERROR(ARRAYFORMULA(AVERAGE(FILTER(Data!D2:D1005 - Data!C2:C1005, Data!B2:B1005 >= DATE(2024,9,1), Data!B2:B1005 < DATE(2024,10,1), Data!W2:W1005 = ""Loss""))),"""")"),"") | K25: =IFERROR(__xludf.DUMMYFUNCTION("IFERROR(ARRAYFORMULA(AVERAGE(FILTER(Data!D2:D1005 - Data!C2:C1005, Data!B2:B1005 >= DATE(2024,10,1), Data!B2:B1005 < DATE(2024,11,1), Data!W2:W1005 = ""Loss""))),"""")"),"") | L25: =IFERROR(__xludf.DUMMYFUNCTION("IFERROR(ARRAYFORMULA(AVERAGE(FILTER(Data!D2:D1005 - Data!C2:C1005, Data!B2:B1005 >= DATE(2024,11,1), Data!B2:B1005 < DATE(2024,12,1), Data!W2:W1005 = ""Loss""))),"""")"),"") | M25: =IFERROR(__xludf.DUMMYFUNCTION("IFERROR(ARRAYFORMULA(AVERAGE(FILTER(Data!D2:D1005 - Data!C2:C1005, Data!B2:B1005 >= DATE(2024,12,1), Data!B2:B1005 < DATE(2025,1,1), Data!W2:W1005 = ""Loss""))),"""")"),"") | Q25: Winrate
A26: 2025 | B26: =IFERROR(__xludf.DUMMYFUNCTION("IFERROR(ARRAYFORMULA(AVERAGE(FILTER(Data!D2:D1005 - Data!C2:C1005, Data!B2:B1005 >= DATE(2025,1,1), Data!B2:B1005 < DATE(2025,2,1), Data!W2:W1005 = ""Loss""))),"""")"),0.010416666666666704) -> 0.010416667 | C26: =IFERROR(__xludf.DUMMYFUNCTION("IFERROR(ARRAYFORMULA(AVERAGE(FILTER(Data!D2:D1005 - Data!C2:C1005, Data!B2:B1005 >= DATE(2025,2,1), Data!B2:B1005 < DATE(2025,3,1), Data!W2:W1005 = ""Loss""))),"""")"),0.03044871794871796) -> 0.030448718 | D26: =IFERROR(__xludf.DUMMYFUNCTION("IFERROR(ARRAYFORMULA(AVERAGE(FILTER(Data!D2:D1005 - Data!C2:C1005, Data!B2:B1005 >= DATE(2025,3,1), Data!B2:B1005 < DATE(2025,4,1), Data!W2:W1005 = ""Win""))),"""")"),0.015972222222222214) -> 0.015972222 | E26: =IFERROR(__xludf.DUMMYFUNCTION("IFERROR(ARRAYFORMULA(AVERAGE(FILTER(Data!D2:D1005 - Data!C2:C1005, Data!B2:B1005 >= DATE(2025,4,1), Data!B2:B1005 < DATE(2025,5,1), Data!W2:W1005 = ""Loss""))),"""")"),0.013020833333333336) -> 0.013020833 | F26: =IFERROR(__xludf.DUMMYFUNCTION("IFERROR(ARRAYFORMULA(AVERAGE(FILTER(Data!D2:D1005 - Data!C2:C1005, Data!B2:B1005 >= DATE(2025,5,1), Data!B2:B1005 < DATE(2025,6,1), Data!W2:W1005 = ""Loss""))),"""")"),"") | G26: =IFERROR(__xludf.DUMMYFUNCTION("IFERROR(ARRAYFORMULA(AVERAGE(FILTER(Data!D2:D1005 - Data!C2:C1005, Data!B2:B1005 >= DATE(2025,6,1), Data!B2:B1005 < DATE(2025,7,1), Data!W2:W1005 = ""Loss""))),"""")"),"") | H26: =IFERROR(__xludf.DUMMYFUNCTION("IFERROR(ARRAYFORMULA(AVERAGE(FILTER(Data!D2:D1005 - Data!C2:C1005, Data!B2:B1005 >= DATE(2025,7,1), Data!B2:B1005 < DATE(2025,8,1), Data!W2:W1005 = ""Loss""))),"""")"),"") | I26: =IFERROR(__xludf.DUMMYFUNCTION("IFERROR(ARRAYFORMULA(AVERAGE(FILTER(Data!D2:D1005 - Data!C2:C1005, Data!B2:B1005 >= DATE(2025,8,1), Data!B2:B1005 < DATE(2025,9,1), Data!W2:W1005 = ""Loss""))),"""")"),"") | J26: =IFERROR(__xludf.DUMMYFUNCTION("IFERROR(ARRAYFORMULA(AVERAGE(FILTER(Data!D2:D1005 - Data!C2:C1005, Data!B2:B1005 >= DATE(2025,9,1), Data!B2:B1005 < DATE(2025,10,1), Data!W2:W1005 = ""Loss""))),"""")"),"") | K26: =IFERROR(__xludf.DUMMYFUNCTION("IFERROR(ARRAYFORMULA(AVERAGE(FILTER(Data!D2:D1005 - Data!C2:C1005, Data!B2:B1005 >= DATE(2025,10,1), Data!B2:B1005 < DATE(2025,11,1), Data!W2:W1005 = ""Loss""))),"""")"),"") | L26: =IFERROR(__xludf.DUMMYFUNCTION("IFERROR(ARRAYFORMULA(AVERAGE(FILTER(Data!D2:D1005 - Data!C2:C1005, Data!B2:B1005 >= DATE(2025,11,1), Data!B2:B1005 < DATE(2025,12,1), Data!W2:W1005 = ""Loss""))),"""")"),"") | M26: =IFERROR(__xludf.DUMMYFUNCTION("IFERROR(ARRAYFORMULA(AVERAGE(FILTER(Data!D2:D1005 - Data!C2:C1005, Data!B2:B1005 >= DATE(2025,12,1), Data!B2:B1005 < DATE(2026,1,1), Data!W2:W1005 = ""Loss""))),"""")"),"") | Q26: Mutation
A27: Average | B27: =IFERROR(AVERAGE(B24:B26),"") -> 0.010416667 | C27: =IFERROR(AVERAGE(C24:C26),"") -> 0.030448718 | D27: =IFERROR(AVERAGE(D24:D26),"") -> 0.015972222 | E27: =IFERROR(AVERAGE(E24:E26),"") -> 0.013020833 | F27: =IFERROR(AVERAGE(F24:F26),"") | G27: =IFERROR(AVERAGE(G24:G26),"") | H27: =IFERROR(AVERAGE(H24:H26),"") | I27: =IFERROR(AVERAGE(I24:I26),"") | ... M27: =IFERROR(AVERAGE(M24:M26),"") | Q27: Max losing streak
B31: Average running time winners
B32: Jan | C32: Feb | D32: mrt | E32: apr | F32: mei | G32: jun | H32: jul | I32: aug | J32: sep | K32: okt | L32: nov | M32: dec
A33: 2023 | B33: =IFERROR(__xludf.DUMMYFUNCTION("IFERROR(ARRAYFORMULA(AVERAGE(FILTER(Data!D2:D1005 - Data!C2:C1005, Data!B2:B1005 >= DATE(2023,1,1), Data!B2:B1005 < DATE(2023,2,1), Data!W2:W1005 = ""Win""))),"""")"),"") | C33: =IFERROR(__xludf.DUMMYFUNCTION("IFERROR(ARRAYFORMULA(AVERAGE(FILTER(Data!D2:D1005 - Data!C2:C1005, Data!B2:B1005 >= DATE(2023,2,1), Data!B2:B1005 < DATE(2023,3,1), Data!W2:W1005 = ""Win""))),"""")"),"") | D33: =IFERROR(__xludf.DUMMYFUNCTION("IFERROR(ARRAYFORMULA(AVERAGE(FILTER(Data!D2:D1005 - Data!C2:C1005, Data!B2:B1005 >= DATE(2023,3,1), Data!B2:B1005 < DATE(2023,4,1), Data!W2:W1005 = ""Win""))),"""")"),"") | E33: =IFERROR(__xludf.DUMMYFUNCTION("IFERROR(ARRAYFORMULA(AVERAGE(FILTER(Data!D2:D1005 - Data!C2:C1005, Data!B2:B1005 >= DATE(2023,4,1), Data!B2:B1005 < DATE(2023,5,1), Data!W2:W1005 = ""Win""))),"""")"),"") | F33: =IFERROR(__xludf.DUMMYFUNCTION("IFERROR(ARRAYFORMULA(AVERAGE(FILTER(Data!D2:D1005 - Data!C2:C1005, Data!B2:B1005 >= DATE(2023,5,1), Data!B2:B1005 < DATE(2023,6,1), Data!W2:W1005 = ""Win""))),"""")"),"") | G33: =IFERROR(__xludf.DUMMYFUNCTION("IFERROR(ARRAYFORMULA(AVERAGE(FILTER(Data!D2:D1005 - Data!C2:C1005, Data!B2:B1005 >= DATE(2023,6,1), Data!B2:B1005 < DATE(2023,7,1), Data!W2:W1005 = ""Win""))),"""")"),"") | H33: =IFERROR(__xludf.DUMMYFUNCTION("IFERROR(ARRAYFORMULA(AVERAGE(FILTER(Data!D2:D1005 - Data!C2:C1005, Data!B2:B1005 >= DATE(2023,7,1), Data!B2:B1005 < DATE(2023,8,1), Data!W2:W1005 = ""Win""))),"""")"),"") | I33: =IFERROR(__xludf.DUMMYFUNCTION("IFERROR(ARRAYFORMULA(AVERAGE(FILTER(Data!D2:D1005 - Data!C2:C1005, Data!B2:B1005 >= DATE(2023,8,1), Data!B2:B1005 < DATE(2023,9,1), Data!W2:W1005 = ""Win""))),"""")"),"") | J33: =IFERROR(__xludf.DUMMYFUNCTION("IFERROR(ARRAYFORMULA(AVERAGE(FILTER(Data!D2:D1005 - Data!C2:C1005, Data!B2:B1005 >= DATE(2023,9,1), Data!B2:B1005 < DATE(2023,10,1), Data!W2:W1005 = ""Win""))),"""")"),"") | K33: =IFERROR(__xludf.DUMMYFUNCTION("IFERROR(ARRAYFORMULA(AVERAGE(FILTER(Data!D2:D1005 - Data!C2:C1005, Data!B2:B1005 >= DATE(2023,10,1), Data!B2:B1005 < DATE(2023,11,1), Data!W2:W1005 = ""Win""))),"""")"),"") | L33: =IFERROR(__xludf.DUMMYFUNCTION("IFERROR(ARRAYFORMULA(AVERAGE(FILTER(Data!D2:D1005 - Data!C2:C1005, Data!B2:B1005 >= DATE(2023,11,1), Data!B2:B1005 < DATE(2023,12,1), Data!W2:W1005 = ""Win""))),"""")"),"") | M33: =IFERROR(__xludf.DUMMYFUNCTION("IFERROR(ARRAYFORMULA(AVERAGE(FILTER(Data!D2:D1005 - Data!C2:C1005, Data!B2:B1005 >= DATE(2023,12,1), Data!B2:B1005 < DATE(2024,1,1), Data!W2:W1005 = ""Win""))),"""")"),"")
A34: 2024 | B34: =IFERROR(__xludf.DUMMYFUNCTION("IFERROR(ARRAYFORMULA(AVERAGE(FILTER(Data!D2:D1005 - Data!C2:C1005, Data!B2:B1005 >= DATE(2024,1,1), Data!B2:B1005 < DATE(2024,2,1), Data!W2:W1005 = ""Win""))),"""")"),"") | C34: =IFERROR(__xludf.DUMMYFUNCTION("IFERROR(ARRAYFORMULA(AVERAGE(FILTER(Data!D2:D1005 - Data!C2:C1005, Data!B2:B1005 >= DATE(2024,2,1), Data!B2:B1005 < DATE(2024,3,1), Data!W2:W1005 = ""Win""))),"""")"),"") | D34: =IFERROR(__xludf.DUMMYFUNCTION("IFERROR(ARRAYFORMULA(AVERAGE(FILTER(Data!D2:D1005 - Data!C2:C1005, Data!B2:B1005 >= DATE(2024,3,1), Data!B2:B1005 < DATE(2024,4,1), Data!W2:W1005 = ""Win""))),"""")"),"") | E34: =IFERROR(__xludf.DUMMYFUNCTION("IFERROR(ARRAYFORMULA(AVERAGE(FILTER(Data!D2:D1005 - Data!C2:C1005, Data!B2:B1005 >= DATE(2024,4,1), Data!B2:B1005 < DATE(2024,5,1), Data!W2:W1005 = ""Win""))),"""")"),"") | F34: =IFERROR(__xludf.DUMMYFUNCTION("IFERROR(ARRAYFORMULA(AVERAGE(FILTER(Data!D2:D1005 - Data!C2:C1005, Data!B2:B1005 >= DATE(2024,5,1), Data!B2:B1005 < DATE(2024,6,1), Data!W2:W1005 = ""Win""))),"""")"),"") | G34: =IFERROR(__xludf.DUMMYFUNCTION("IFERROR(ARRAYFORMULA(AVERAGE(FILTER(Data!D2:D1005 - Data!C2:C1005, Data!B2:B1005 >= DATE(2024,6,1), Data!B2:B1005 < DATE(2024,7,1), Data!W2:W1005 = ""Win""))),"""")"),"") | H34: =IFERROR(__xludf.DUMMYFUNCTION("IFERROR(ARRAYFORMULA(AVERAGE(FILTER(Data!D2:D1005 - Data!C2:C1005, Data!B2:B1005 >= DATE(2024,7,1), Data!B2:B1005 < DATE(2024,8,1), Data!W2:W1005 = ""Win""))),"""")"),"") | I34: =IFERROR(__xludf.DUMMYFUNCTION("IFERROR(ARRAYFORMULA(AVERAGE(FILTER(Data!D2:D1005 - Data!C2:C1005, Data!B2:B1005 >= DATE(2024,8,1), Data!B2:B1005 < DATE(2024,9,1), Data!W2:W1005 = ""Win""))),"""")"),"") | J34: =IFERROR(__xludf.DUMMYFUNCTION("IFERROR(ARRAYFORMULA(AVERAGE(FILTER(Data!D2:D1005 - Data!C2:C1005, Data!B2:B1005 >= DATE(2024,9,1), Data!B2:B1005 < DATE(2024,10,1), Data!W2:W1005 = ""Win""))),"""")"),"") | K34: =IFERROR(__xludf.DUMMYFUNCTION("IFERROR(ARRAYFORMULA(AVERAGE(FILTER(Data!D2:D1005 - Data!C2:C1005, Data!B2:B1005 >= DATE(2024,10,1), Data!B2:B1005 < DATE(2024,11,1), Data!W2:W1005 = ""Win""))),"""")"),"") | L34: =IFERROR(__xludf.DUMMYFUNCTION("IFERROR(ARRAYFORMULA(AVERAGE(FILTER(Data!D2:D1005 - Data!C2:C1005, Data!B2:B1005 >= DATE(2024,11,1), Data!B2:B1005 < DATE(2024,12,1), Data!W2:W1005 = ""Win""))),"""")"),"") | M34: =IFERROR(__xludf.DUMMYFUNCTION("IFERROR(ARRAYFORMULA(AVERAGE(FILTER(Data!D2:D1005 - Data!C2:C1005, Data!B2:B1005 >= DATE(2024,12,1), Data!B2:B1005 < DATE(2025,1,1), Data!W2:W1005 = ""Win""))),"""")"),"")
A35: 2025 | B35: =IFERROR(__xludf.DUMMYFUNCTION("IFERROR(ARRAYFORMULA(AVERAGE(FILTER(Data!D2:D1005 - Data!C2:C1005, Data!B2:B1005 >= DATE(2025,1,1), Data!B2:B1005 < DATE(2025,2,1), Data!W2:W1005 = ""Win""))),"""")"),0.01822916666666667) -> 0.018229167 | C35: =IFERROR(__xludf.DUMMYFUNCTION("IFERROR(ARRAYFORMULA(AVERAGE(FILTER(Data!D2:D1005 - Data!C2:C1005, Data!B2:B1005 >= DATE(2025,2,1), Data!B2:B1005 < DATE(2025,3,1), Data!W2:W1005 = ""Win""))),"""")"),0.020254629629629636) -> 0.02025463 | D35: =IFERROR(__xludf.DUMMYFUNCTION("IFERROR(ARRAYFORMULA(AVERAGE(FILTER(Data!D2:D1005 - Data!C2:C1005, Data!B2:B1005 >= DATE(2025,3,1), Data!B2:B1005 < DATE(2025,4,1), Data!W2:W1005 = ""Win""))),"""")"),0.015972222222222214) -> 0.015972222 | E35: =IFERROR(__xludf.DUMMYFUNCTION("IFERROR(ARRAYFORMULA(AVERAGE(FILTER(Data!D2:D1005 - Data!C2:C1005, Data!B2:B1005 >= DATE(2025,4,1), Data!B2:B1005 < DATE(2025,5,1), Data!W2:W1005 = ""Win""))),"""")"),0.01909722222222221) -> 0.019097222 | F35: =IFERROR(__xludf.DUMMYFUNCTION("IFERROR(ARRAYFORMULA(AVERAGE(FILTER(Data!D2:D1005 - Data!C2:C1005, Data!B2:B1005 >= DATE(2025,5,1), Data!B2:B1005 < DATE(2025,6,1), Data!W2:W1005 = ""Win""))),"""")"),"") | G35: =IFERROR(__xludf.DUMMYFUNCTION("IFERROR(ARRAYFORMULA(AVERAGE(FILTER(Data!D2:D1005 - Data!C2:C1005, Data!B2:B1005 >= DATE(2025,6,1), Data!B2:B1005 < DATE(2025,7,1), Data!W2:W1005 = ""Win""))),"""")"),"") | H35: =IFERROR(__xludf.DUMMYFUNCTION("IFERROR(ARRAYFORMULA(AVERAGE(FILTER(Data!D2:D1005 - Data!C2:C1005, Data!B2:B1005 >= DATE(2025,7,1), Data!B2:B1005 < DATE(2025,8,1), Data!W2:W1005 = ""Win""))),"""")"),"") | I35: =IFERROR(__xludf.DUMMYFUNCTION("IFERROR(ARRAYFORMULA(AVERAGE(FILTER(Data!D2:D1005 - Data!C2:C1005, Data!B2:B1005 >= DATE(2025,8,1), Data!B2:B1005 < DATE(2025,9,1), Data!W2:W1005 = ""Win""))),"""")"),"") | J35: =IFERROR(__xludf.DUMMYFUNCTION("IFERROR(ARRAYFORMULA(AVERAGE(FILTER(Data!D2:D1005 - Data!C2:C1005, Data!B2:B1005 >= DATE(2025,9,1), Data!B2:B1005 < DATE(2025,10,1), Data!W2:W1005 = ""Win""))),"""")"),"") | K35: =IFERROR(__xludf.DUMMYFUNCTION("IFERROR(ARRAYFORMULA(AVERAGE(FILTER(Data!D2:D1005 - Data!C2:C1005, Data!B2:B1005 >= DATE(2025,10,1), Data!B2:B1005 < DATE(2025,11,1), Data!W2:W1005 = ""Win""))),"""")"),"") | L35: =IFERROR(__xludf.DUMMYFUNCTION("IFERROR(ARRAYFORMULA(AVERAGE(FILTER(Data!D2:D1005 - Data!C2:C1005, Data!B2:B1005 >= DATE(2025,11,1), Data!B2:B1005 < DATE(2025,12,1), Data!W2:W1005 = ""Win""))),"""")"),"") | M35: =IFERROR(__xludf.DUMMYFUNCTION("IFERROR(ARRAYFORMULA(AVERAGE(FILTER(Data!D2:D1005 - Data!C2:C1005, Data!B2:B1005 >= DATE(2025,12,1), Data!B2:B1005 < DATE(2026,1,1), Data!W2:W1005 = ""Win""))),"""")"),"")
A36: Average | B36: =IFERROR(AVERAGE(B33:B35),"") -> 0.018229167 | C36: =IFERROR(AVERAGE(C33:C35),"") -> 0.02025463 | D36: =IFERROR(AVERAGE(D33:D35),"") -> 0.015972222 | E36: =IFERROR(AVERAGE(E33:E35),"") -> 0.019097222 | F36: =IFERROR(AVERAGE(F33:F35),"") | G36: =IFERROR(AVERAGE(G33:G35),"") | H36: =IFERROR(AVERAGE(H33:H35),"") | I36: =IFERROR(AVERAGE(I33:I35),"") | ... M36: =IFERROR(AVERAGE(M33:M35),"")
B40: Max drawdown
B41: Jan | C41: Feb | D41: mrt | E41: apr | F41: mei | G41: jun | H41: jul | I41: aug | J41: sep | K41: okt | L41: nov | M41: dec
A42: 2023 | B42: =MAXIFS(Data!Y2:Y1005, Data!B2:B1005, ">="&DATE(2023,1,1), Data!B2:B1005, "<"&DATE(2023,2,1)) -> 0 | C42: =MAXIFS(Data!Y2:Y1005, Data!B2:B1005, ">="&DATE(2023,2,1), Data!B2:B1005, "<"&DATE(2023,3,1)) -> 0 | D42: =MAXIFS(Data!Y2:Y1005, Data!B2:B1005, ">="&DATE(2023,3,1), Data!B2:B1005, "<"&DATE(2023,4,1)) -> 0 | E42: =MAXIFS(Data!Y2:Y1005, Data!B2:B1005, ">="&DATE(2023,4,1), Data!B2:B1005, "<"&DATE(2023,5,1)) -> 0 | F42: =MAXIFS(Data!Y2:Y1005, Data!B2:B1005, ">="&DATE(2023,5,1), Data!B2:B1005, "<"&DATE(2023,6,1)) -> 0 | G42: =MAXIFS(Data!Y2:Y1005, Data!B2:B1005, ">="&DATE(2023,6,1), Data!B2:B1005, "<"&DATE(2023,7,1)) -> 0 | H42: =MAXIFS(Data!Y2:Y1005, Data!B2:B1005, ">="&DATE(2023,7,1), Data!B2:B1005, "<"&DATE(2023,8,1)) -> 0 | I42: =MAXIFS(Data!Y2:Y1005, Data!B2:B1005, ">="&DATE(2023,8,1), Data!B2:B1005, "<"&DATE(2023,9,1)) -> 0 | J42: =MAXIFS(Data!Y2:Y1005, Data!B2:B1005, ">="&DATE(2023,9,1), Data!B2:B1005, "<"&DATE(2023,10,1)) -> 0 | K42: =MAXIFS(Data!Y2:Y1005, Data!B2:B1005, ">="&DATE(2023,10,1), Data!B2:B1005, "<"&DATE(2023,11,1)) -> 0 | L42: =MAXIFS(Data!Y2:Y1005, Data!B2:B1005, ">="&DATE(2023,11,1), Data!B2:B1005, "<"&DATE(2023,12,1)) -> 0 | M42: =MAXIFS(Data!Y2:Y1005, Data!B2:B1005, ">="&DATE(2023,12,1), Data!B2:B1005, "<"&DATE(2024,1,1)) -> 0
A43: 2024 | B43: =MAXIFS(Data!Y2:Y1005, Data!B2:B1005, ">="&DATE(2024,1,1), Data!B2:B1005, "<"&DATE(2024,2,1)) -> 0 | C43: =MAXIFS(Data!Y2:Y1005, Data!B2:B1005, ">="&DATE(2024,2,1), Data!B2:B1005, "<"&DATE(2024,3,1)) -> 0 | D43: =MAXIFS(Data!Y2:Y1005, Data!B2:B1005, ">="&DATE(2024,3,1), Data!B2:B1005, "<"&DATE(2024,4,1)) -> 0 | E43: =MAXIFS(Data!Y2:Y1005, Data!B2:B1005, ">="&DATE(2024,4,1), Data!B2:B1005, "<"&DATE(2024,5,1)) -> 0 | F43: =MAXIFS(Data!Y2:Y1005, Data!B2:B1005, ">="&DATE(2024,5,1), Data!B2:B1005, "<"&DATE(2024,6,1)) -> 0 | G43: =MAXIFS(Data!Y2:Y1005, Data!B2:B1005, ">="&DATE(2024,6,1), Data!B2:B1005, "<"&DATE(2024,7,1)) -> 0 | H43: =MAXIFS(Data!Y2:Y1005, Data!B2:B1005, ">="&DATE(2024,7,1), Data!B2:B1005, "<"&DATE(2024,8,1)) -> 0 | I43: =MAXIFS(Data!Y2:Y1005, Data!B2:B1005, ">="&DATE(2024,8,1), Data!B2:B1005, "<"&DATE(2024,9,1)) -> 0 | J43: =MAXIFS(Data!Y2:Y1005, Data!B2:B1005, ">="&DATE(2024,9,1), Data!B2:B1005, "<"&DATE(2024,10,1)) -> 0 | K43: =MAXIFS(Data!Y2:Y1005, Data!B2:B1005, ">="&DATE(2024,10,1), Data!B2:B1005, "<"&DATE(2024,11,1)) -> 0 | L43: =MAXIFS(Data!Y2:Y1005, Data!B2:B1005, ">="&DATE(2024,11,1), Data!B2:B1005, "<"&DATE(2024,12,1)) -> 0 | M43: =MAXIFS(Data!Y2:Y1005, Data!B2:B1005, ">="&DATE(2024,12,1), Data!B2:B1005, "<"&DATE(2025,1,1)) -> 0
A44: 2025 | B44: =MAXIFS(Data!Y2:Y1005, Data!B2:B1005, ">="&DATE(2025,1,1), Data!B2:B1005, "<"&DATE(2025,2,1)) -> 17.7 | C44: =MAXIFS(Data!Y2:Y1005, Data!B2:B1005, ">="&DATE(2025,2,1), Data!B2:B1005, "<"&DATE(2025,3,1)) -> 29.1 | D44: =MAXIFS(Data!Y2:Y1005, Data!B2:B1005, ">="&DATE(2025,3,1), Data!B2:B1005, "<"&DATE(2025,4,1)) -> 30.1 | E44: =MAXIFS(Data!Y2:Y1005, Data!B2:B1005, ">="&DATE(2025,4,1), Data!B2:B1005, "<"&DATE(2025,5,1)) -> 51.6 | F44: =MAXIFS(Data!Y2:Y1005, Data!B2:B1005, ">="&DATE(2025,5,1), Data!B2:B1005, "<"&DATE(2025,6,1)) -> 0 | G44: =MAXIFS(Data!Y2:Y1005, Data!B2:B1005, ">="&DATE(2025,6,1), Data!B2:B1005, "<"&DATE(2025,7,1)) -> 0 | H44: =MAXIFS(Data!Y2:Y1005, Data!B2:B1005, ">="&DATE(2025,7,1), Data!B2:B1005, "<"&DATE(2025,8,1)) -> 0 | I44: =MAXIFS(Data!Y2:Y1005, Data!B2:B1005, ">="&DATE(2025,8,1), Data!B2:B1005, "<"&DATE(2025,9,1)) -> 0 | J44: =MAXIFS(Data!Y2:Y1005, Data!B2:B1005, ">="&DATE(2025,9,1), Data!B2:B1005, "<"&DATE(2025,10,1)) -> 0 | K44: =MAXIFS(Data!Y2:Y1005, Data!B2:B1005, ">="&DATE(2025,10,1), Data!B2:B1005, "<"&DATE(2025,11,1)) -> 0 | L44: =MAXIFS(Data!Y2:Y1005, Data!B2:B1005, ">="&DATE(2025,11,1), Data!B2:B1005, "<"&DATE(2025,12,1)) -> 0 | M44: =MAXIFS(Data!Y2:Y1005, Data!B2:B1005, ">="&DATE(2025,12,1), Data!B2:B1005, "<"&DATE(2026,1,1)) -> 0
A45: Maximum | B45: =MAX(B43:B44) -> 17.7 | C45: =MAX(C43:C44) -> 29.1 | D45: =MAX(D43:D44) -> 30.1 | E45: =MAX(E43:E44) -> 51.6 | F45: =MAX(F43:F44) -> 0 | G45: =MAX(G43:G44) -> 0 | H45: =MAX(H43:H44) -> 0 | I45: =MAX(I43:I44) -> 0 | ... M45: =MAX(M43:M44) -> 0
B49: Max RR where all trades would still win
B50: Jan | C50: Feb | D50: mrt | E50: apr | F50: mei | G50: jun | H50: jul | I50: aug | J50: sep | K50: okt | L50: nov | M50: dec
A51: 2023 | B51: =MINIFS(Data!Z2:Z1005, Data!W2:W1005, "Win", Data!B2:B1005, ">="&DATE(2023,1,1), Data!B2:B1005, "<"&DATE(2023,2,1)) -> 0 | C51: =MINIFS(Data!Z2:Z1005, Data!W2:W1005, "Win", Data!B2:B1005, ">="&DATE(2023,2,1), Data!B2:B1005, "<"&DATE(2023,3,1)) -> 0 | D51: =MINIFS(Data!Z2:Z1005, Data!W2:W1005, "Win", Data!B2:B1005, ">="&DATE(2023,3,1), Data!B2:B1005, "<"&DATE(2023,4,1)) -> 0 | E51: =MINIFS(Data!Z2:Z1005, Data!W2:W1005, "Win", Data!B2:B1005, ">="&DATE(2023,4,1), Data!B2:B1005, "<"&DATE(2023,5,1)) -> 0 | F51: =MINIFS(Data!Z2:Z1005, Data!W2:W1005, "Win", Data!B2:B1005, ">="&DATE(2023,5,1), Data!B2:B1005, "<"&DATE(2023,6,1)) -> 0 | G51: =MINIFS(Data!Z2:Z1005, Data!W2:W1005, "Win", Data!B2:B1005, ">="&DATE(2023,6,1), Data!B2:B1005, "<"&DATE(2023,7,1)) -> 0 | H51: =MINIFS(Data!Z2:Z1005, Data!W2:W1005, "Win", Data!B2:B1005, ">="&DATE(2023,7,1), Data!B2:B1005, "<"&DATE(2023,8,1)) -> 0 | I51: =MINIFS(Data!Z2:Z1005, Data!W2:W1005, "Win", Data!B2:B1005, ">="&DATE(2023,8,1), Data!B2:B1005, "<"&DATE(2023,9,1)) -> 0 | J51: =MINIFS(Data!Z2:Z1005, Data!W2:W1005, "Win", Data!B2:B1005, ">="&DATE(2023,9,1), Data!B2:B1005, "<"&DATE(2023,10,1)) -> 0 | K51: =MINIFS(Data!Z2:Z1005, Data!W2:W1005, "Win", Data!B2:B1005, ">="&DATE(2023,10,1), Data!B2:B1005, "<"&DATE(2023,11,1)) -> 0 | L51: =MINIFS(Data!Z2:Z1005, Data!W2:W1005, "Win", Data!B2:B1005, ">="&DATE(2023,11,1), Data!B2:B1005, "<"&DATE(2023,12,1)) -> 0 | M51: =MINIFS(Data!Z2:Z1005, Data!W2:W1005, "Win", Data!B2:B1005, ">="&DATE(2023,12,1), Data!B2:B1005, "<"&DATE(2024,1,1)) -> 0
